{
 "cells": [
  {
   "cell_type": "code",
   "execution_count": 30,
   "metadata": {},
   "outputs": [
    {
     "name": "stdout",
     "output_type": "stream",
     "text": [
      "[9 0 0 ... 3 0 5]\n"
     ]
    }
   ],
   "source": [
    "import tensorflow as tf\n",
    "from tensorflow.keras.datasets import fashion_mnist\n",
    "from tensorflow.keras.models import Sequential\n",
    "from tensorflow.keras.layers import Dense , Dropout , Input\n",
    "from tensorflow.keras.utils import to_categorical\n",
    "from sklearn.metrics import confusion_matrix,classification_report\n",
    "import numpy as np\n",
    "import pandas\n",
    "(x_train ,y_train) , (x_test,y_test) = fashion_mnist.load_data()\n",
    "print(y_train)\n",
    "x_train = x_train/255.0\n",
    "y_train = y_train/255.0\n"
   ]
  },
  {
   "cell_type": "code",
   "execution_count": 41,
   "metadata": {},
   "outputs": [],
   "source": [
    "x_train = x_train.reshape(x_train.shape[0],-1)\n",
    "x_test = x_test.reshape(x_test.shape[0],-1)\n",
    "\n",
    "y_train = to_categorical(y_train,10)\n",
    "y_test = to_categorical(y_test,10)"
   ]
  },
  {
   "cell_type": "code",
   "execution_count": 46,
   "metadata": {},
   "outputs": [
    {
     "name": "stdout",
     "output_type": "stream",
     "text": [
      "Epoch 1/5\n"
     ]
    },
    {
     "ename": "ValueError",
     "evalue": "in user code:\n\n    File \"c:\\Users\\Patam\\AppData\\Local\\Programs\\Python\\Python310\\lib\\site-packages\\keras\\engine\\training.py\", line 1249, in train_function  *\n        return step_function(self, iterator)\n    File \"c:\\Users\\Patam\\AppData\\Local\\Programs\\Python\\Python310\\lib\\site-packages\\keras\\engine\\training.py\", line 1233, in step_function  **\n        outputs = model.distribute_strategy.run(run_step, args=(data,))\n    File \"c:\\Users\\Patam\\AppData\\Local\\Programs\\Python\\Python310\\lib\\site-packages\\keras\\engine\\training.py\", line 1222, in run_step  **\n        outputs = model.train_step(data)\n    File \"c:\\Users\\Patam\\AppData\\Local\\Programs\\Python\\Python310\\lib\\site-packages\\keras\\engine\\training.py\", line 1024, in train_step\n        loss = self.compute_loss(x, y, y_pred, sample_weight)\n    File \"c:\\Users\\Patam\\AppData\\Local\\Programs\\Python\\Python310\\lib\\site-packages\\keras\\engine\\training.py\", line 1082, in compute_loss\n        return self.compiled_loss(\n    File \"c:\\Users\\Patam\\AppData\\Local\\Programs\\Python\\Python310\\lib\\site-packages\\keras\\engine\\compile_utils.py\", line 265, in __call__\n        loss_value = loss_obj(y_t, y_p, sample_weight=sw)\n    File \"c:\\Users\\Patam\\AppData\\Local\\Programs\\Python\\Python310\\lib\\site-packages\\keras\\losses.py\", line 152, in __call__\n        losses = call_fn(y_true, y_pred)\n    File \"c:\\Users\\Patam\\AppData\\Local\\Programs\\Python\\Python310\\lib\\site-packages\\keras\\losses.py\", line 284, in call  **\n        return ag_fn(y_true, y_pred, **self._fn_kwargs)\n    File \"c:\\Users\\Patam\\AppData\\Local\\Programs\\Python\\Python310\\lib\\site-packages\\keras\\losses.py\", line 2004, in categorical_crossentropy\n        return backend.categorical_crossentropy(\n    File \"c:\\Users\\Patam\\AppData\\Local\\Programs\\Python\\Python310\\lib\\site-packages\\keras\\backend.py\", line 5532, in categorical_crossentropy\n        target.shape.assert_is_compatible_with(output.shape)\n\n    ValueError: Shapes (32, 10, 10, 10, 10) and (32, 10) are incompatible\n",
     "output_type": "error",
     "traceback": [
      "\u001b[1;31m---------------------------------------------------------------------------\u001b[0m",
      "\u001b[1;31mValueError\u001b[0m                                Traceback (most recent call last)",
      "Input \u001b[1;32mIn [46]\u001b[0m, in \u001b[0;36m<module>\u001b[1;34m\u001b[0m\n\u001b[0;32m      1\u001b[0m model \u001b[38;5;241m=\u001b[39m Sequential([\n\u001b[0;32m      2\u001b[0m   Input(shape\u001b[38;5;241m=\u001b[39m(\u001b[38;5;241m784\u001b[39m,)),\n\u001b[0;32m      3\u001b[0m   Dense(\u001b[38;5;241m128\u001b[39m , activation \u001b[38;5;241m=\u001b[39m \u001b[38;5;124m'\u001b[39m\u001b[38;5;124mrelu\u001b[39m\u001b[38;5;124m'\u001b[39m),\n\u001b[0;32m      4\u001b[0m   Dropout(\u001b[38;5;241m0.2\u001b[39m),\n\u001b[0;32m      5\u001b[0m   Dense(\u001b[38;5;241m10\u001b[39m,activation\u001b[38;5;241m=\u001b[39m\u001b[38;5;124m'\u001b[39m\u001b[38;5;124msoftmax\u001b[39m\u001b[38;5;124m'\u001b[39m)\n\u001b[0;32m      6\u001b[0m  ])\n\u001b[0;32m      8\u001b[0m model\u001b[38;5;241m.\u001b[39mcompile(optimizer\u001b[38;5;241m=\u001b[39m\u001b[38;5;124m'\u001b[39m\u001b[38;5;124madam\u001b[39m\u001b[38;5;124m'\u001b[39m,loss\u001b[38;5;241m=\u001b[39m\u001b[38;5;124m'\u001b[39m\u001b[38;5;124mcategorical_crossentropy\u001b[39m\u001b[38;5;124m'\u001b[39m\n\u001b[0;32m      9\u001b[0m               ,metrics \u001b[38;5;241m=\u001b[39m [\u001b[38;5;124m'\u001b[39m\u001b[38;5;124maccuracy\u001b[39m\u001b[38;5;124m'\u001b[39m])\n\u001b[1;32m---> 10\u001b[0m \u001b[43mmodel\u001b[49m\u001b[38;5;241;43m.\u001b[39;49m\u001b[43mfit\u001b[49m\u001b[43m(\u001b[49m\u001b[43mx_train\u001b[49m\u001b[43m,\u001b[49m\u001b[43my_train\u001b[49m\u001b[43m,\u001b[49m\u001b[43mepochs\u001b[49m\u001b[38;5;241;43m=\u001b[39;49m\u001b[38;5;241;43m5\u001b[39;49m\u001b[43m,\u001b[49m\u001b[43mvalidation_data\u001b[49m\u001b[38;5;241;43m=\u001b[39;49m\u001b[43m(\u001b[49m\u001b[43mx_test\u001b[49m\u001b[43m,\u001b[49m\u001b[43my_test\u001b[49m\u001b[43m)\u001b[49m\u001b[43m)\u001b[49m\n\u001b[0;32m     11\u001b[0m test_loss , test_accuracy \u001b[38;5;241m=\u001b[39m model\u001b[38;5;241m.\u001b[39mevaluate(x_test,y_test)\n",
      "File \u001b[1;32mc:\\Users\\Patam\\AppData\\Local\\Programs\\Python\\Python310\\lib\\site-packages\\keras\\utils\\traceback_utils.py:70\u001b[0m, in \u001b[0;36mfilter_traceback.<locals>.error_handler\u001b[1;34m(*args, **kwargs)\u001b[0m\n\u001b[0;32m     67\u001b[0m     filtered_tb \u001b[38;5;241m=\u001b[39m _process_traceback_frames(e\u001b[38;5;241m.\u001b[39m__traceback__)\n\u001b[0;32m     68\u001b[0m     \u001b[38;5;66;03m# To get the full stack trace, call:\u001b[39;00m\n\u001b[0;32m     69\u001b[0m     \u001b[38;5;66;03m# `tf.debugging.disable_traceback_filtering()`\u001b[39;00m\n\u001b[1;32m---> 70\u001b[0m     \u001b[38;5;28;01mraise\u001b[39;00m e\u001b[38;5;241m.\u001b[39mwith_traceback(filtered_tb) \u001b[38;5;28;01mfrom\u001b[39;00m \u001b[38;5;28mNone\u001b[39m\n\u001b[0;32m     71\u001b[0m \u001b[38;5;28;01mfinally\u001b[39;00m:\n\u001b[0;32m     72\u001b[0m     \u001b[38;5;28;01mdel\u001b[39;00m filtered_tb\n",
      "File \u001b[1;32m~\\AppData\\Local\\Temp\\__autograph_generated_filehj6mx3ac.py:15\u001b[0m, in \u001b[0;36mouter_factory.<locals>.inner_factory.<locals>.tf__train_function\u001b[1;34m(iterator)\u001b[0m\n\u001b[0;32m     13\u001b[0m \u001b[38;5;28;01mtry\u001b[39;00m:\n\u001b[0;32m     14\u001b[0m     do_return \u001b[38;5;241m=\u001b[39m \u001b[38;5;28;01mTrue\u001b[39;00m\n\u001b[1;32m---> 15\u001b[0m     retval_ \u001b[38;5;241m=\u001b[39m ag__\u001b[38;5;241m.\u001b[39mconverted_call(ag__\u001b[38;5;241m.\u001b[39mld(step_function), (ag__\u001b[38;5;241m.\u001b[39mld(\u001b[38;5;28mself\u001b[39m), ag__\u001b[38;5;241m.\u001b[39mld(iterator)), \u001b[38;5;28;01mNone\u001b[39;00m, fscope)\n\u001b[0;32m     16\u001b[0m \u001b[38;5;28;01mexcept\u001b[39;00m:\n\u001b[0;32m     17\u001b[0m     do_return \u001b[38;5;241m=\u001b[39m \u001b[38;5;28;01mFalse\u001b[39;00m\n",
      "\u001b[1;31mValueError\u001b[0m: in user code:\n\n    File \"c:\\Users\\Patam\\AppData\\Local\\Programs\\Python\\Python310\\lib\\site-packages\\keras\\engine\\training.py\", line 1249, in train_function  *\n        return step_function(self, iterator)\n    File \"c:\\Users\\Patam\\AppData\\Local\\Programs\\Python\\Python310\\lib\\site-packages\\keras\\engine\\training.py\", line 1233, in step_function  **\n        outputs = model.distribute_strategy.run(run_step, args=(data,))\n    File \"c:\\Users\\Patam\\AppData\\Local\\Programs\\Python\\Python310\\lib\\site-packages\\keras\\engine\\training.py\", line 1222, in run_step  **\n        outputs = model.train_step(data)\n    File \"c:\\Users\\Patam\\AppData\\Local\\Programs\\Python\\Python310\\lib\\site-packages\\keras\\engine\\training.py\", line 1024, in train_step\n        loss = self.compute_loss(x, y, y_pred, sample_weight)\n    File \"c:\\Users\\Patam\\AppData\\Local\\Programs\\Python\\Python310\\lib\\site-packages\\keras\\engine\\training.py\", line 1082, in compute_loss\n        return self.compiled_loss(\n    File \"c:\\Users\\Patam\\AppData\\Local\\Programs\\Python\\Python310\\lib\\site-packages\\keras\\engine\\compile_utils.py\", line 265, in __call__\n        loss_value = loss_obj(y_t, y_p, sample_weight=sw)\n    File \"c:\\Users\\Patam\\AppData\\Local\\Programs\\Python\\Python310\\lib\\site-packages\\keras\\losses.py\", line 152, in __call__\n        losses = call_fn(y_true, y_pred)\n    File \"c:\\Users\\Patam\\AppData\\Local\\Programs\\Python\\Python310\\lib\\site-packages\\keras\\losses.py\", line 284, in call  **\n        return ag_fn(y_true, y_pred, **self._fn_kwargs)\n    File \"c:\\Users\\Patam\\AppData\\Local\\Programs\\Python\\Python310\\lib\\site-packages\\keras\\losses.py\", line 2004, in categorical_crossentropy\n        return backend.categorical_crossentropy(\n    File \"c:\\Users\\Patam\\AppData\\Local\\Programs\\Python\\Python310\\lib\\site-packages\\keras\\backend.py\", line 5532, in categorical_crossentropy\n        target.shape.assert_is_compatible_with(output.shape)\n\n    ValueError: Shapes (32, 10, 10, 10, 10) and (32, 10) are incompatible\n"
     ]
    }
   ],
   "source": [
    "model = Sequential([\n",
    "  Input(shape=(784,)),\n",
    "  Dense(128 , activation = 'relu'),\n",
    "  Dropout(0.2),\n",
    "  Dense(10,activation='softmax')\n",
    " ])\n",
    "\n",
    "model.compile(optimizer='adam',loss='categorical_crossentropy'\n",
    "              ,metrics = ['accuracy'])\n",
    "model.fit(x_train,y_train,epochs=5,validation_data=(x_test,y_test))\n",
    "test_loss , test_accuracy = model.evaluate(x_test,y_test)"
   ]
  },
  {
   "cell_type": "code",
   "execution_count": null,
   "metadata": {},
   "outputs": [],
   "source": []
  }
 ],
 "metadata": {
  "kernelspec": {
   "display_name": "Python 3",
   "language": "python",
   "name": "python3"
  },
  "language_info": {
   "codemirror_mode": {
    "name": "ipython",
    "version": 3
   },
   "file_extension": ".py",
   "mimetype": "text/x-python",
   "name": "python",
   "nbconvert_exporter": "python",
   "pygments_lexer": "ipython3",
   "version": "3.10.2"
  }
 },
 "nbformat": 4,
 "nbformat_minor": 2
}
